<?xml version="1.0" encoding="UTF-8"?>
<testng-results ignored="3" total="13" passed="1" failed="9" skipped="0">
  <reporter-output>
  </reporter-output>
  <suite started-at="2023-09-05T11:19:53 EDT" name="Failed suite [crossBrowserTestingSuite]" finished-at="2023-09-05T11:21:42 EDT" duration-ms="108619">
    <groups>
    </groups>
    <test started-at="2023-09-05T11:19:53 EDT" name="CHROME(failed)" finished-at="2023-09-05T11:20:28 EDT" duration-ms="35217">
      <class name="com.tekarck.testCases.TC02_ValidLoginToSalesForce">
        <test-method is-config="true" signature="setUp(java.lang.String,java.lang.String)[pri:0, instance:com.tekarck.testCases.TC02_ValidLoginToSalesForce@6d3a388c]" started-at="2023-09-05T11:19:53 EDT" name="setUp" finished-at="2023-09-05T11:19:58 EDT" duration-ms="4364" status="PASS">
          <params>
            <param index="0">
              <value>
                <![CDATA[chrome]]>
              </value>
            </param>
            <param index="1">
              <value>
                <![CDATA[https://login.salesforce.com/]]>
              </value>
            </param>
          </params>
          <reporter-output>
          </reporter-output>
        </test-method> <!-- setUp -->
        <test-method signature="loginToSalesForceAppUsingDataProviders(java.lang.reflect.Method,java.lang.String,java.lang.String)[pri:0, instance:com.tekarck.testCases.TC02_ValidLoginToSalesForce@6d3a388c]" started-at="2023-09-05T11:19:58 EDT" name="loginToSalesForceAppUsingDataProviders" data-provider="LoginDataProvider" finished-at="2023-09-05T11:20:04 EDT" duration-ms="6211" status="FAIL">
          <params>
            <param index="0">
              <value>
                <![CDATA[void com.tekarck.testCases.TC02_ValidLoginToSalesForce.loginToSalesForceAppUsingDataProviders(java.lang.reflect.Method,java.lang.String,java.lang.String) throws org.apache.poi.openxml4j.exceptions.InvalidFormatException,java.io.IOException]]>
              </value>
            </param>
            <param index="1">
              <value>
                <![CDATA[anusha@tek.com]]>
              </value>
            </param>
            <param index="2">
              <value>
                <![CDATA[Sumedh]]>
              </value>
            </param>
          </params>
          <exception class="java.lang.AssertionError">
            <message>
              <![CDATA[Failed to login for User Name and password :anusha@tek.com  Sumedh expected [true] but found [false]]]>
            </message>
            <full-stacktrace>
              <![CDATA[java.lang.AssertionError: Failed to login for User Name and password :anusha@tek.com  Sumedh expected [true] but found [false]
at org.testng.Assert.fail(Assert.java:110)
at org.testng.Assert.failNotEquals(Assert.java:1413)
at org.testng.Assert.assertTrue(Assert.java:56)
at com.tekarck.testCases.TC02_ValidLoginToSalesForce.loginToSalesForceAppUsingDataProviders(TC02_ValidLoginToSalesForce.java:164)
at java.base/jdk.internal.reflect.DirectMethodHandleAccessor.invoke(DirectMethodHandleAccessor.java:104)
at java.base/java.lang.reflect.Method.invoke(Method.java:578)
at org.testng.internal.invokers.MethodInvocationHelper.invokeMethod(MethodInvocationHelper.java:139)
at org.testng.internal.invokers.TestInvoker.invokeMethod(TestInvoker.java:677)
at org.testng.internal.invokers.TestInvoker.invokeTestMethod(TestInvoker.java:221)
at org.testng.internal.invokers.MethodRunner.runInSequence(MethodRunner.java:50)
at org.testng.internal.invokers.TestInvoker$MethodInvocationAgent.invoke(TestInvoker.java:962)
at org.testng.internal.invokers.TestInvoker.invokeTestMethods(TestInvoker.java:194)
at org.testng.internal.invokers.TestMethodWorker.invokeTestMethods(TestMethodWorker.java:148)
at org.testng.internal.invokers.TestMethodWorker.run(TestMethodWorker.java:128)
at java.base/java.util.ArrayList.forEach(ArrayList.java:1511)
at org.testng.TestRunner.privateRun(TestRunner.java:806)
at org.testng.TestRunner.run(TestRunner.java:601)
at org.testng.SuiteRunner.runTest(SuiteRunner.java:433)
at org.testng.SuiteRunner.runSequentially(SuiteRunner.java:427)
at org.testng.SuiteRunner.privateRun(SuiteRunner.java:387)
at org.testng.SuiteRunner.run(SuiteRunner.java:330)
at org.testng.SuiteRunnerWorker.runSuite(SuiteRunnerWorker.java:52)
at org.testng.SuiteRunnerWorker.run(SuiteRunnerWorker.java:95)
at org.testng.TestNG.runSuitesSequentially(TestNG.java:1256)
at org.testng.TestNG.runSuitesLocally(TestNG.java:1176)
at org.testng.TestNG.runSuites(TestNG.java:1099)
at org.testng.TestNG.run(TestNG.java:1067)
at org.testng.remote.AbstractRemoteTestNG.run(AbstractRemoteTestNG.java:115)
at org.testng.remote.RemoteTestNG.initAndRun(RemoteTestNG.java:251)
at org.testng.remote.RemoteTestNG.main(RemoteTestNG.java:77)
]]>
            </full-stacktrace>
          </exception> <!-- java.lang.AssertionError -->
          <reporter-output>
          </reporter-output>
        </test-method> <!-- loginToSalesForceAppUsingDataProviders -->
        <test-method signature="loginToSalesForceAppUsingDataProviders(java.lang.reflect.Method,java.lang.String,java.lang.String)[pri:0, instance:com.tekarck.testCases.TC02_ValidLoginToSalesForce@6d3a388c]" started-at="2023-09-05T11:20:05 EDT" name="loginToSalesForceAppUsingDataProviders" data-provider="LoginDataProvider" finished-at="2023-09-05T11:20:10 EDT" duration-ms="5627" status="FAIL">
          <params>
            <param index="0">
              <value>
                <![CDATA[void com.tekarck.testCases.TC02_ValidLoginToSalesForce.loginToSalesForceAppUsingDataProviders(java.lang.reflect.Method,java.lang.String,java.lang.String) throws org.apache.poi.openxml4j.exceptions.InvalidFormatException,java.io.IOException]]>
              </value>
            </param>
            <param index="1">
              <value>
                <![CDATA[anusha@tek]]>
              </value>
            </param>
            <param index="2">
              <value>
                <![CDATA[Sumedh@03]]>
              </value>
            </param>
          </params>
          <exception class="java.lang.AssertionError">
            <message>
              <![CDATA[Failed to login for User Name and password :anusha@tek  Sumedh@03 expected [true] but found [false]]]>
            </message>
            <full-stacktrace>
              <![CDATA[java.lang.AssertionError: Failed to login for User Name and password :anusha@tek  Sumedh@03 expected [true] but found [false]
at org.testng.Assert.fail(Assert.java:110)
at org.testng.Assert.failNotEquals(Assert.java:1413)
at org.testng.Assert.assertTrue(Assert.java:56)
at com.tekarck.testCases.TC02_ValidLoginToSalesForce.loginToSalesForceAppUsingDataProviders(TC02_ValidLoginToSalesForce.java:164)
at java.base/jdk.internal.reflect.DirectMethodHandleAccessor.invoke(DirectMethodHandleAccessor.java:104)
at java.base/java.lang.reflect.Method.invoke(Method.java:578)
at org.testng.internal.invokers.MethodInvocationHelper.invokeMethod(MethodInvocationHelper.java:139)
at org.testng.internal.invokers.TestInvoker.invokeMethod(TestInvoker.java:677)
at org.testng.internal.invokers.TestInvoker.invokeTestMethod(TestInvoker.java:221)
at org.testng.internal.invokers.MethodRunner.runInSequence(MethodRunner.java:50)
at org.testng.internal.invokers.TestInvoker$MethodInvocationAgent.invoke(TestInvoker.java:962)
at org.testng.internal.invokers.TestInvoker.invokeTestMethods(TestInvoker.java:194)
at org.testng.internal.invokers.TestMethodWorker.invokeTestMethods(TestMethodWorker.java:148)
at org.testng.internal.invokers.TestMethodWorker.run(TestMethodWorker.java:128)
at java.base/java.util.ArrayList.forEach(ArrayList.java:1511)
at org.testng.TestRunner.privateRun(TestRunner.java:806)
at org.testng.TestRunner.run(TestRunner.java:601)
at org.testng.SuiteRunner.runTest(SuiteRunner.java:433)
at org.testng.SuiteRunner.runSequentially(SuiteRunner.java:427)
at org.testng.SuiteRunner.privateRun(SuiteRunner.java:387)
at org.testng.SuiteRunner.run(SuiteRunner.java:330)
at org.testng.SuiteRunnerWorker.runSuite(SuiteRunnerWorker.java:52)
at org.testng.SuiteRunnerWorker.run(SuiteRunnerWorker.java:95)
at org.testng.TestNG.runSuitesSequentially(TestNG.java:1256)
at org.testng.TestNG.runSuitesLocally(TestNG.java:1176)
at org.testng.TestNG.runSuites(TestNG.java:1099)
at org.testng.TestNG.run(TestNG.java:1067)
at org.testng.remote.AbstractRemoteTestNG.run(AbstractRemoteTestNG.java:115)
at org.testng.remote.RemoteTestNG.initAndRun(RemoteTestNG.java:251)
at org.testng.remote.RemoteTestNG.main(RemoteTestNG.java:77)
]]>
            </full-stacktrace>
          </exception> <!-- java.lang.AssertionError -->
          <reporter-output>
          </reporter-output>
        </test-method> <!-- loginToSalesForceAppUsingDataProviders -->
        <test-method signature="loginToSalesForceAppUsingDataProviders(java.lang.reflect.Method,java.lang.String,java.lang.String)[pri:0, instance:com.tekarck.testCases.TC02_ValidLoginToSalesForce@6d3a388c]" started-at="2023-09-05T11:20:10 EDT" name="loginToSalesForceAppUsingDataProviders" data-provider="LoginDataProvider" finished-at="2023-09-05T11:20:28 EDT" duration-ms="17715" status="FAIL">
          <params>
            <param index="0">
              <value>
                <![CDATA[void com.tekarck.testCases.TC02_ValidLoginToSalesForce.loginToSalesForceAppUsingDataProviders(java.lang.reflect.Method,java.lang.String,java.lang.String) throws org.apache.poi.openxml4j.exceptions.InvalidFormatException,java.io.IOException]]>
              </value>
            </param>
            <param index="1">
              <value>
                <![CDATA[anusha@t.com]]>
              </value>
            </param>
            <param index="2">
              <value>
                <![CDATA[Anusha]]>
              </value>
            </param>
          </params>
          <exception class="java.lang.AssertionError">
            <message>
              <![CDATA[Failed to login for User Name and password :anusha@t.com  Anusha expected [true] but found [false]]]>
            </message>
            <full-stacktrace>
              <![CDATA[java.lang.AssertionError: Failed to login for User Name and password :anusha@t.com  Anusha expected [true] but found [false]
at org.testng.Assert.fail(Assert.java:110)
at org.testng.Assert.failNotEquals(Assert.java:1413)
at org.testng.Assert.assertTrue(Assert.java:56)
at com.tekarck.testCases.TC02_ValidLoginToSalesForce.loginToSalesForceAppUsingDataProviders(TC02_ValidLoginToSalesForce.java:164)
at java.base/jdk.internal.reflect.DirectMethodHandleAccessor.invoke(DirectMethodHandleAccessor.java:104)
at java.base/java.lang.reflect.Method.invoke(Method.java:578)
at org.testng.internal.invokers.MethodInvocationHelper.invokeMethod(MethodInvocationHelper.java:139)
at org.testng.internal.invokers.TestInvoker.invokeMethod(TestInvoker.java:677)
at org.testng.internal.invokers.TestInvoker.invokeTestMethod(TestInvoker.java:221)
at org.testng.internal.invokers.MethodRunner.runInSequence(MethodRunner.java:50)
at org.testng.internal.invokers.TestInvoker$MethodInvocationAgent.invoke(TestInvoker.java:962)
at org.testng.internal.invokers.TestInvoker.invokeTestMethods(TestInvoker.java:194)
at org.testng.internal.invokers.TestMethodWorker.invokeTestMethods(TestMethodWorker.java:148)
at org.testng.internal.invokers.TestMethodWorker.run(TestMethodWorker.java:128)
at java.base/java.util.ArrayList.forEach(ArrayList.java:1511)
at org.testng.TestRunner.privateRun(TestRunner.java:806)
at org.testng.TestRunner.run(TestRunner.java:601)
at org.testng.SuiteRunner.runTest(SuiteRunner.java:433)
at org.testng.SuiteRunner.runSequentially(SuiteRunner.java:427)
at org.testng.SuiteRunner.privateRun(SuiteRunner.java:387)
at org.testng.SuiteRunner.run(SuiteRunner.java:330)
at org.testng.SuiteRunnerWorker.runSuite(SuiteRunnerWorker.java:52)
at org.testng.SuiteRunnerWorker.run(SuiteRunnerWorker.java:95)
at org.testng.TestNG.runSuitesSequentially(TestNG.java:1256)
at org.testng.TestNG.runSuitesLocally(TestNG.java:1176)
at org.testng.TestNG.runSuites(TestNG.java:1099)
at org.testng.TestNG.run(TestNG.java:1067)
at org.testng.remote.AbstractRemoteTestNG.run(AbstractRemoteTestNG.java:115)
at org.testng.remote.RemoteTestNG.initAndRun(RemoteTestNG.java:251)
at org.testng.remote.RemoteTestNG.main(RemoteTestNG.java:77)
]]>
            </full-stacktrace>
          </exception> <!-- java.lang.AssertionError -->
          <reporter-output>
          </reporter-output>
        </test-method> <!-- loginToSalesForceAppUsingDataProviders -->
        <test-method is-config="true" signature="tearDown()[pri:0, instance:com.tekarck.testCases.TC02_ValidLoginToSalesForce@6d3a388c]" started-at="2023-09-05T11:20:28 EDT" name="tearDown" finished-at="2023-09-05T11:20:28 EDT" duration-ms="61" status="PASS">
          <reporter-output>
          </reporter-output>
        </test-method> <!-- tearDown -->
      </class> <!-- com.tekarck.testCases.TC02_ValidLoginToSalesForce -->
    </test> <!-- CHROME(failed) -->
    <test started-at="2023-09-05T11:20:29 EDT" name="EDGE(failed)" finished-at="2023-09-05T11:21:05 EDT" duration-ms="36001">
      <class name="com.tekarck.testCases.TC02_ValidLoginToSalesForce">
        <test-method is-config="true" signature="setUp(java.lang.String,java.lang.String)[pri:0, instance:com.tekarck.testCases.TC02_ValidLoginToSalesForce@53fdffa1]" started-at="2023-09-05T11:20:29 EDT" name="setUp" finished-at="2023-09-05T11:20:34 EDT" duration-ms="5133" status="PASS">
          <params>
            <param index="0">
              <value>
                <![CDATA[edge]]>
              </value>
            </param>
            <param index="1">
              <value>
                <![CDATA[https://login.salesforce.com/]]>
              </value>
            </param>
          </params>
          <reporter-output>
          </reporter-output>
        </test-method> <!-- setUp -->
        <test-method signature="loginToSalesForceAppUsingDataProviders(java.lang.reflect.Method,java.lang.String,java.lang.String)[pri:0, instance:com.tekarck.testCases.TC02_ValidLoginToSalesForce@53fdffa1]" started-at="2023-09-05T11:20:34 EDT" name="loginToSalesForceAppUsingDataProviders" data-provider="LoginDataProvider" finished-at="2023-09-05T11:20:40 EDT" duration-ms="6047" status="FAIL">
          <params>
            <param index="0">
              <value>
                <![CDATA[void com.tekarck.testCases.TC02_ValidLoginToSalesForce.loginToSalesForceAppUsingDataProviders(java.lang.reflect.Method,java.lang.String,java.lang.String) throws org.apache.poi.openxml4j.exceptions.InvalidFormatException,java.io.IOException]]>
              </value>
            </param>
            <param index="1">
              <value>
                <![CDATA[anusha@tek.com]]>
              </value>
            </param>
            <param index="2">
              <value>
                <![CDATA[Sumedh]]>
              </value>
            </param>
          </params>
          <exception class="java.lang.AssertionError">
            <message>
              <![CDATA[Failed to login for User Name and password :anusha@tek.com  Sumedh expected [true] but found [false]]]>
            </message>
            <full-stacktrace>
              <![CDATA[java.lang.AssertionError: Failed to login for User Name and password :anusha@tek.com  Sumedh expected [true] but found [false]
at org.testng.Assert.fail(Assert.java:110)
at org.testng.Assert.failNotEquals(Assert.java:1413)
at org.testng.Assert.assertTrue(Assert.java:56)
at com.tekarck.testCases.TC02_ValidLoginToSalesForce.loginToSalesForceAppUsingDataProviders(TC02_ValidLoginToSalesForce.java:164)
at java.base/jdk.internal.reflect.DirectMethodHandleAccessor.invoke(DirectMethodHandleAccessor.java:104)
at java.base/java.lang.reflect.Method.invoke(Method.java:578)
at org.testng.internal.invokers.MethodInvocationHelper.invokeMethod(MethodInvocationHelper.java:139)
at org.testng.internal.invokers.TestInvoker.invokeMethod(TestInvoker.java:677)
at org.testng.internal.invokers.TestInvoker.invokeTestMethod(TestInvoker.java:221)
at org.testng.internal.invokers.MethodRunner.runInSequence(MethodRunner.java:50)
at org.testng.internal.invokers.TestInvoker$MethodInvocationAgent.invoke(TestInvoker.java:962)
at org.testng.internal.invokers.TestInvoker.invokeTestMethods(TestInvoker.java:194)
at org.testng.internal.invokers.TestMethodWorker.invokeTestMethods(TestMethodWorker.java:148)
at org.testng.internal.invokers.TestMethodWorker.run(TestMethodWorker.java:128)
at java.base/java.util.ArrayList.forEach(ArrayList.java:1511)
at org.testng.TestRunner.privateRun(TestRunner.java:806)
at org.testng.TestRunner.run(TestRunner.java:601)
at org.testng.SuiteRunner.runTest(SuiteRunner.java:433)
at org.testng.SuiteRunner.runSequentially(SuiteRunner.java:427)
at org.testng.SuiteRunner.privateRun(SuiteRunner.java:387)
at org.testng.SuiteRunner.run(SuiteRunner.java:330)
at org.testng.SuiteRunnerWorker.runSuite(SuiteRunnerWorker.java:52)
at org.testng.SuiteRunnerWorker.run(SuiteRunnerWorker.java:95)
at org.testng.TestNG.runSuitesSequentially(TestNG.java:1256)
at org.testng.TestNG.runSuitesLocally(TestNG.java:1176)
at org.testng.TestNG.runSuites(TestNG.java:1099)
at org.testng.TestNG.run(TestNG.java:1067)
at org.testng.remote.AbstractRemoteTestNG.run(AbstractRemoteTestNG.java:115)
at org.testng.remote.RemoteTestNG.initAndRun(RemoteTestNG.java:251)
at org.testng.remote.RemoteTestNG.main(RemoteTestNG.java:77)
]]>
            </full-stacktrace>
          </exception> <!-- java.lang.AssertionError -->
          <reporter-output>
          </reporter-output>
        </test-method> <!-- loginToSalesForceAppUsingDataProviders -->
        <test-method signature="loginToSalesForceAppUsingDataProviders(java.lang.reflect.Method,java.lang.String,java.lang.String)[pri:0, instance:com.tekarck.testCases.TC02_ValidLoginToSalesForce@53fdffa1]" started-at="2023-09-05T11:20:40 EDT" name="loginToSalesForceAppUsingDataProviders" data-provider="LoginDataProvider" finished-at="2023-09-05T11:20:46 EDT" duration-ms="5562" status="FAIL">
          <params>
            <param index="0">
              <value>
                <![CDATA[void com.tekarck.testCases.TC02_ValidLoginToSalesForce.loginToSalesForceAppUsingDataProviders(java.lang.reflect.Method,java.lang.String,java.lang.String) throws org.apache.poi.openxml4j.exceptions.InvalidFormatException,java.io.IOException]]>
              </value>
            </param>
            <param index="1">
              <value>
                <![CDATA[anusha@tek]]>
              </value>
            </param>
            <param index="2">
              <value>
                <![CDATA[Sumedh@03]]>
              </value>
            </param>
          </params>
          <exception class="java.lang.AssertionError">
            <message>
              <![CDATA[Failed to login for User Name and password :anusha@tek  Sumedh@03 expected [true] but found [false]]]>
            </message>
            <full-stacktrace>
              <![CDATA[java.lang.AssertionError: Failed to login for User Name and password :anusha@tek  Sumedh@03 expected [true] but found [false]
at org.testng.Assert.fail(Assert.java:110)
at org.testng.Assert.failNotEquals(Assert.java:1413)
at org.testng.Assert.assertTrue(Assert.java:56)
at com.tekarck.testCases.TC02_ValidLoginToSalesForce.loginToSalesForceAppUsingDataProviders(TC02_ValidLoginToSalesForce.java:164)
at java.base/jdk.internal.reflect.DirectMethodHandleAccessor.invoke(DirectMethodHandleAccessor.java:104)
at java.base/java.lang.reflect.Method.invoke(Method.java:578)
at org.testng.internal.invokers.MethodInvocationHelper.invokeMethod(MethodInvocationHelper.java:139)
at org.testng.internal.invokers.TestInvoker.invokeMethod(TestInvoker.java:677)
at org.testng.internal.invokers.TestInvoker.invokeTestMethod(TestInvoker.java:221)
at org.testng.internal.invokers.MethodRunner.runInSequence(MethodRunner.java:50)
at org.testng.internal.invokers.TestInvoker$MethodInvocationAgent.invoke(TestInvoker.java:962)
at org.testng.internal.invokers.TestInvoker.invokeTestMethods(TestInvoker.java:194)
at org.testng.internal.invokers.TestMethodWorker.invokeTestMethods(TestMethodWorker.java:148)
at org.testng.internal.invokers.TestMethodWorker.run(TestMethodWorker.java:128)
at java.base/java.util.ArrayList.forEach(ArrayList.java:1511)
at org.testng.TestRunner.privateRun(TestRunner.java:806)
at org.testng.TestRunner.run(TestRunner.java:601)
at org.testng.SuiteRunner.runTest(SuiteRunner.java:433)
at org.testng.SuiteRunner.runSequentially(SuiteRunner.java:427)
at org.testng.SuiteRunner.privateRun(SuiteRunner.java:387)
at org.testng.SuiteRunner.run(SuiteRunner.java:330)
at org.testng.SuiteRunnerWorker.runSuite(SuiteRunnerWorker.java:52)
at org.testng.SuiteRunnerWorker.run(SuiteRunnerWorker.java:95)
at org.testng.TestNG.runSuitesSequentially(TestNG.java:1256)
at org.testng.TestNG.runSuitesLocally(TestNG.java:1176)
at org.testng.TestNG.runSuites(TestNG.java:1099)
at org.testng.TestNG.run(TestNG.java:1067)
at org.testng.remote.AbstractRemoteTestNG.run(AbstractRemoteTestNG.java:115)
at org.testng.remote.RemoteTestNG.initAndRun(RemoteTestNG.java:251)
at org.testng.remote.RemoteTestNG.main(RemoteTestNG.java:77)
]]>
            </full-stacktrace>
          </exception> <!-- java.lang.AssertionError -->
          <reporter-output>
          </reporter-output>
        </test-method> <!-- loginToSalesForceAppUsingDataProviders -->
        <test-method signature="loginToSalesForceAppUsingDataProviders(java.lang.reflect.Method,java.lang.String,java.lang.String)[pri:0, instance:com.tekarck.testCases.TC02_ValidLoginToSalesForce@53fdffa1]" started-at="2023-09-05T11:20:46 EDT" name="loginToSalesForceAppUsingDataProviders" data-provider="LoginDataProvider" finished-at="2023-09-05T11:21:04 EDT" duration-ms="18508" status="FAIL">
          <params>
            <param index="0">
              <value>
                <![CDATA[void com.tekarck.testCases.TC02_ValidLoginToSalesForce.loginToSalesForceAppUsingDataProviders(java.lang.reflect.Method,java.lang.String,java.lang.String) throws org.apache.poi.openxml4j.exceptions.InvalidFormatException,java.io.IOException]]>
              </value>
            </param>
            <param index="1">
              <value>
                <![CDATA[anusha@t.com]]>
              </value>
            </param>
            <param index="2">
              <value>
                <![CDATA[Anusha]]>
              </value>
            </param>
          </params>
          <exception class="java.lang.AssertionError">
            <message>
              <![CDATA[Failed to login for User Name and password :anusha@t.com  Anusha expected [true] but found [false]]]>
            </message>
            <full-stacktrace>
              <![CDATA[java.lang.AssertionError: Failed to login for User Name and password :anusha@t.com  Anusha expected [true] but found [false]
at org.testng.Assert.fail(Assert.java:110)
at org.testng.Assert.failNotEquals(Assert.java:1413)
at org.testng.Assert.assertTrue(Assert.java:56)
at com.tekarck.testCases.TC02_ValidLoginToSalesForce.loginToSalesForceAppUsingDataProviders(TC02_ValidLoginToSalesForce.java:164)
at java.base/jdk.internal.reflect.DirectMethodHandleAccessor.invoke(DirectMethodHandleAccessor.java:104)
at java.base/java.lang.reflect.Method.invoke(Method.java:578)
at org.testng.internal.invokers.MethodInvocationHelper.invokeMethod(MethodInvocationHelper.java:139)
at org.testng.internal.invokers.TestInvoker.invokeMethod(TestInvoker.java:677)
at org.testng.internal.invokers.TestInvoker.invokeTestMethod(TestInvoker.java:221)
at org.testng.internal.invokers.MethodRunner.runInSequence(MethodRunner.java:50)
at org.testng.internal.invokers.TestInvoker$MethodInvocationAgent.invoke(TestInvoker.java:962)
at org.testng.internal.invokers.TestInvoker.invokeTestMethods(TestInvoker.java:194)
at org.testng.internal.invokers.TestMethodWorker.invokeTestMethods(TestMethodWorker.java:148)
at org.testng.internal.invokers.TestMethodWorker.run(TestMethodWorker.java:128)
at java.base/java.util.ArrayList.forEach(ArrayList.java:1511)
at org.testng.TestRunner.privateRun(TestRunner.java:806)
at org.testng.TestRunner.run(TestRunner.java:601)
at org.testng.SuiteRunner.runTest(SuiteRunner.java:433)
at org.testng.SuiteRunner.runSequentially(SuiteRunner.java:427)
at org.testng.SuiteRunner.privateRun(SuiteRunner.java:387)
at org.testng.SuiteRunner.run(SuiteRunner.java:330)
at org.testng.SuiteRunnerWorker.runSuite(SuiteRunnerWorker.java:52)
at org.testng.SuiteRunnerWorker.run(SuiteRunnerWorker.java:95)
at org.testng.TestNG.runSuitesSequentially(TestNG.java:1256)
at org.testng.TestNG.runSuitesLocally(TestNG.java:1176)
at org.testng.TestNG.runSuites(TestNG.java:1099)
at org.testng.TestNG.run(TestNG.java:1067)
at org.testng.remote.AbstractRemoteTestNG.run(AbstractRemoteTestNG.java:115)
at org.testng.remote.RemoteTestNG.initAndRun(RemoteTestNG.java:251)
at org.testng.remote.RemoteTestNG.main(RemoteTestNG.java:77)
]]>
            </full-stacktrace>
          </exception> <!-- java.lang.AssertionError -->
          <reporter-output>
          </reporter-output>
        </test-method> <!-- loginToSalesForceAppUsingDataProviders -->
        <test-method is-config="true" signature="tearDown()[pri:0, instance:com.tekarck.testCases.TC02_ValidLoginToSalesForce@53fdffa1]" started-at="2023-09-05T11:21:04 EDT" name="tearDown" finished-at="2023-09-05T11:21:05 EDT" duration-ms="206" status="PASS">
          <reporter-output>
          </reporter-output>
        </test-method> <!-- tearDown -->
      </class> <!-- com.tekarck.testCases.TC02_ValidLoginToSalesForce -->
    </test> <!-- EDGE(failed) -->
    <test started-at="2023-09-05T11:21:05 EDT" name="FIREFOX(failed)" finished-at="2023-09-05T11:21:42 EDT" duration-ms="36952">
      <class name="com.tekarck.testCases.TC03_CheckRememberMe">
        <test-method is-config="true" signature="setUp(java.lang.String,java.lang.String)[pri:0, instance:com.tekarck.testCases.TC03_CheckRememberMe@73e22a3d]" started-at="2023-09-05T11:21:05 EDT" name="setUp" finished-at="2023-09-05T11:21:08 EDT" duration-ms="2965" status="PASS">
          <params>
            <param index="0">
              <value>
                <![CDATA[firefox]]>
              </value>
            </param>
            <param index="1">
              <value>
                <![CDATA[https://login.salesforce.com/]]>
              </value>
            </param>
          </params>
          <reporter-output>
          </reporter-output>
        </test-method> <!-- setUp -->
        <test-method signature="loginAndCheckRememberMe()[pri:0, instance:com.tekarck.testCases.TC03_CheckRememberMe@73e22a3d]" started-at="2023-09-05T11:21:08 EDT" name="loginAndCheckRememberMe" finished-at="2023-09-05T11:21:15 EDT" duration-ms="7714" status="PASS">
          <reporter-output>
          </reporter-output>
        </test-method> <!-- loginAndCheckRememberMe -->
        <test-method is-config="true" signature="tearDown()[pri:0, instance:com.tekarck.testCases.TC03_CheckRememberMe@73e22a3d]" started-at="2023-09-05T11:21:15 EDT" name="tearDown" finished-at="2023-09-05T11:21:16 EDT" duration-ms="1017" status="PASS">
          <reporter-output>
          </reporter-output>
        </test-method> <!-- tearDown -->
      </class> <!-- com.tekarck.testCases.TC03_CheckRememberMe -->
      <class name="com.tekarck.testCases.TC02_ValidLoginToSalesForce">
        <test-method is-config="true" signature="setUp(java.lang.String,java.lang.String)[pri:0, instance:com.tekarck.testCases.TC02_ValidLoginToSalesForce@47faa49c]" started-at="2023-09-05T11:21:16 EDT" name="setUp" finished-at="2023-09-05T11:21:19 EDT" duration-ms="2567" status="PASS">
          <params>
            <param index="0">
              <value>
                <![CDATA[firefox]]>
              </value>
            </param>
            <param index="1">
              <value>
                <![CDATA[https://login.salesforce.com/]]>
              </value>
            </param>
          </params>
          <reporter-output>
          </reporter-output>
        </test-method> <!-- setUp -->
        <test-method signature="loginToSalesForceAppUsingDataProviders(java.lang.reflect.Method,java.lang.String,java.lang.String)[pri:0, instance:com.tekarck.testCases.TC02_ValidLoginToSalesForce@47faa49c]" started-at="2023-09-05T11:21:19 EDT" name="loginToSalesForceAppUsingDataProviders" data-provider="LoginDataProvider" finished-at="2023-09-05T11:21:25 EDT" duration-ms="5606" status="FAIL">
          <params>
            <param index="0">
              <value>
                <![CDATA[void com.tekarck.testCases.TC02_ValidLoginToSalesForce.loginToSalesForceAppUsingDataProviders(java.lang.reflect.Method,java.lang.String,java.lang.String) throws org.apache.poi.openxml4j.exceptions.InvalidFormatException,java.io.IOException]]>
              </value>
            </param>
            <param index="1">
              <value>
                <![CDATA[anusha@tek.com]]>
              </value>
            </param>
            <param index="2">
              <value>
                <![CDATA[Sumedh]]>
              </value>
            </param>
          </params>
          <exception class="java.lang.AssertionError">
            <message>
              <![CDATA[Failed to login for User Name and password :anusha@tek.com  Sumedh expected [true] but found [false]]]>
            </message>
            <full-stacktrace>
              <![CDATA[java.lang.AssertionError: Failed to login for User Name and password :anusha@tek.com  Sumedh expected [true] but found [false]
at org.testng.Assert.fail(Assert.java:110)
at org.testng.Assert.failNotEquals(Assert.java:1413)
at org.testng.Assert.assertTrue(Assert.java:56)
at com.tekarck.testCases.TC02_ValidLoginToSalesForce.loginToSalesForceAppUsingDataProviders(TC02_ValidLoginToSalesForce.java:164)
at java.base/jdk.internal.reflect.DirectMethodHandleAccessor.invoke(DirectMethodHandleAccessor.java:104)
at java.base/java.lang.reflect.Method.invoke(Method.java:578)
at org.testng.internal.invokers.MethodInvocationHelper.invokeMethod(MethodInvocationHelper.java:139)
at org.testng.internal.invokers.TestInvoker.invokeMethod(TestInvoker.java:677)
at org.testng.internal.invokers.TestInvoker.invokeTestMethod(TestInvoker.java:221)
at org.testng.internal.invokers.MethodRunner.runInSequence(MethodRunner.java:50)
at org.testng.internal.invokers.TestInvoker$MethodInvocationAgent.invoke(TestInvoker.java:962)
at org.testng.internal.invokers.TestInvoker.invokeTestMethods(TestInvoker.java:194)
at org.testng.internal.invokers.TestMethodWorker.invokeTestMethods(TestMethodWorker.java:148)
at org.testng.internal.invokers.TestMethodWorker.run(TestMethodWorker.java:128)
at java.base/java.util.ArrayList.forEach(ArrayList.java:1511)
at org.testng.TestRunner.privateRun(TestRunner.java:806)
at org.testng.TestRunner.run(TestRunner.java:601)
at org.testng.SuiteRunner.runTest(SuiteRunner.java:433)
at org.testng.SuiteRunner.runSequentially(SuiteRunner.java:427)
at org.testng.SuiteRunner.privateRun(SuiteRunner.java:387)
at org.testng.SuiteRunner.run(SuiteRunner.java:330)
at org.testng.SuiteRunnerWorker.runSuite(SuiteRunnerWorker.java:52)
at org.testng.SuiteRunnerWorker.run(SuiteRunnerWorker.java:95)
at org.testng.TestNG.runSuitesSequentially(TestNG.java:1256)
at org.testng.TestNG.runSuitesLocally(TestNG.java:1176)
at org.testng.TestNG.runSuites(TestNG.java:1099)
at org.testng.TestNG.run(TestNG.java:1067)
at org.testng.remote.AbstractRemoteTestNG.run(AbstractRemoteTestNG.java:115)
at org.testng.remote.RemoteTestNG.initAndRun(RemoteTestNG.java:251)
at org.testng.remote.RemoteTestNG.main(RemoteTestNG.java:77)
]]>
            </full-stacktrace>
          </exception> <!-- java.lang.AssertionError -->
          <reporter-output>
          </reporter-output>
        </test-method> <!-- loginToSalesForceAppUsingDataProviders -->
        <test-method signature="loginToSalesForceAppUsingDataProviders(java.lang.reflect.Method,java.lang.String,java.lang.String)[pri:0, instance:com.tekarck.testCases.TC02_ValidLoginToSalesForce@47faa49c]" started-at="2023-09-05T11:21:25 EDT" name="loginToSalesForceAppUsingDataProviders" data-provider="LoginDataProvider" finished-at="2023-09-05T11:21:30 EDT" duration-ms="5455" status="FAIL">
          <params>
            <param index="0">
              <value>
                <![CDATA[void com.tekarck.testCases.TC02_ValidLoginToSalesForce.loginToSalesForceAppUsingDataProviders(java.lang.reflect.Method,java.lang.String,java.lang.String) throws org.apache.poi.openxml4j.exceptions.InvalidFormatException,java.io.IOException]]>
              </value>
            </param>
            <param index="1">
              <value>
                <![CDATA[anusha@tek]]>
              </value>
            </param>
            <param index="2">
              <value>
                <![CDATA[Sumedh@03]]>
              </value>
            </param>
          </params>
          <exception class="java.lang.AssertionError">
            <message>
              <![CDATA[Failed to login for User Name and password :anusha@tek  Sumedh@03 expected [true] but found [false]]]>
            </message>
            <full-stacktrace>
              <![CDATA[java.lang.AssertionError: Failed to login for User Name and password :anusha@tek  Sumedh@03 expected [true] but found [false]
at org.testng.Assert.fail(Assert.java:110)
at org.testng.Assert.failNotEquals(Assert.java:1413)
at org.testng.Assert.assertTrue(Assert.java:56)
at com.tekarck.testCases.TC02_ValidLoginToSalesForce.loginToSalesForceAppUsingDataProviders(TC02_ValidLoginToSalesForce.java:164)
at java.base/jdk.internal.reflect.DirectMethodHandleAccessor.invoke(DirectMethodHandleAccessor.java:104)
at java.base/java.lang.reflect.Method.invoke(Method.java:578)
at org.testng.internal.invokers.MethodInvocationHelper.invokeMethod(MethodInvocationHelper.java:139)
at org.testng.internal.invokers.TestInvoker.invokeMethod(TestInvoker.java:677)
at org.testng.internal.invokers.TestInvoker.invokeTestMethod(TestInvoker.java:221)
at org.testng.internal.invokers.MethodRunner.runInSequence(MethodRunner.java:50)
at org.testng.internal.invokers.TestInvoker$MethodInvocationAgent.invoke(TestInvoker.java:962)
at org.testng.internal.invokers.TestInvoker.invokeTestMethods(TestInvoker.java:194)
at org.testng.internal.invokers.TestMethodWorker.invokeTestMethods(TestMethodWorker.java:148)
at org.testng.internal.invokers.TestMethodWorker.run(TestMethodWorker.java:128)
at java.base/java.util.ArrayList.forEach(ArrayList.java:1511)
at org.testng.TestRunner.privateRun(TestRunner.java:806)
at org.testng.TestRunner.run(TestRunner.java:601)
at org.testng.SuiteRunner.runTest(SuiteRunner.java:433)
at org.testng.SuiteRunner.runSequentially(SuiteRunner.java:427)
at org.testng.SuiteRunner.privateRun(SuiteRunner.java:387)
at org.testng.SuiteRunner.run(SuiteRunner.java:330)
at org.testng.SuiteRunnerWorker.runSuite(SuiteRunnerWorker.java:52)
at org.testng.SuiteRunnerWorker.run(SuiteRunnerWorker.java:95)
at org.testng.TestNG.runSuitesSequentially(TestNG.java:1256)
at org.testng.TestNG.runSuitesLocally(TestNG.java:1176)
at org.testng.TestNG.runSuites(TestNG.java:1099)
at org.testng.TestNG.run(TestNG.java:1067)
at org.testng.remote.AbstractRemoteTestNG.run(AbstractRemoteTestNG.java:115)
at org.testng.remote.RemoteTestNG.initAndRun(RemoteTestNG.java:251)
at org.testng.remote.RemoteTestNG.main(RemoteTestNG.java:77)
]]>
            </full-stacktrace>
          </exception> <!-- java.lang.AssertionError -->
          <reporter-output>
          </reporter-output>
        </test-method> <!-- loginToSalesForceAppUsingDataProviders -->
        <test-method signature="loginToSalesForceAppUsingDataProviders(java.lang.reflect.Method,java.lang.String,java.lang.String)[pri:0, instance:com.tekarck.testCases.TC02_ValidLoginToSalesForce@47faa49c]" started-at="2023-09-05T11:21:30 EDT" name="loginToSalesForceAppUsingDataProviders" data-provider="LoginDataProvider" finished-at="2023-09-05T11:21:41 EDT" duration-ms="10508" status="FAIL">
          <params>
            <param index="0">
              <value>
                <![CDATA[void com.tekarck.testCases.TC02_ValidLoginToSalesForce.loginToSalesForceAppUsingDataProviders(java.lang.reflect.Method,java.lang.String,java.lang.String) throws org.apache.poi.openxml4j.exceptions.InvalidFormatException,java.io.IOException]]>
              </value>
            </param>
            <param index="1">
              <value>
                <![CDATA[anusha@t.com]]>
              </value>
            </param>
            <param index="2">
              <value>
                <![CDATA[Anusha]]>
              </value>
            </param>
          </params>
          <exception class="java.lang.AssertionError">
            <message>
              <![CDATA[Failed to login for User Name and password :anusha@t.com  Anusha expected [true] but found [false]]]>
            </message>
            <full-stacktrace>
              <![CDATA[java.lang.AssertionError: Failed to login for User Name and password :anusha@t.com  Anusha expected [true] but found [false]
at org.testng.Assert.fail(Assert.java:110)
at org.testng.Assert.failNotEquals(Assert.java:1413)
at org.testng.Assert.assertTrue(Assert.java:56)
at com.tekarck.testCases.TC02_ValidLoginToSalesForce.loginToSalesForceAppUsingDataProviders(TC02_ValidLoginToSalesForce.java:164)
at java.base/jdk.internal.reflect.DirectMethodHandleAccessor.invoke(DirectMethodHandleAccessor.java:104)
at java.base/java.lang.reflect.Method.invoke(Method.java:578)
at org.testng.internal.invokers.MethodInvocationHelper.invokeMethod(MethodInvocationHelper.java:139)
at org.testng.internal.invokers.TestInvoker.invokeMethod(TestInvoker.java:677)
at org.testng.internal.invokers.TestInvoker.invokeTestMethod(TestInvoker.java:221)
at org.testng.internal.invokers.MethodRunner.runInSequence(MethodRunner.java:50)
at org.testng.internal.invokers.TestInvoker$MethodInvocationAgent.invoke(TestInvoker.java:962)
at org.testng.internal.invokers.TestInvoker.invokeTestMethods(TestInvoker.java:194)
at org.testng.internal.invokers.TestMethodWorker.invokeTestMethods(TestMethodWorker.java:148)
at org.testng.internal.invokers.TestMethodWorker.run(TestMethodWorker.java:128)
at java.base/java.util.ArrayList.forEach(ArrayList.java:1511)
at org.testng.TestRunner.privateRun(TestRunner.java:806)
at org.testng.TestRunner.run(TestRunner.java:601)
at org.testng.SuiteRunner.runTest(SuiteRunner.java:433)
at org.testng.SuiteRunner.runSequentially(SuiteRunner.java:427)
at org.testng.SuiteRunner.privateRun(SuiteRunner.java:387)
at org.testng.SuiteRunner.run(SuiteRunner.java:330)
at org.testng.SuiteRunnerWorker.runSuite(SuiteRunnerWorker.java:52)
at org.testng.SuiteRunnerWorker.run(SuiteRunnerWorker.java:95)
at org.testng.TestNG.runSuitesSequentially(TestNG.java:1256)
at org.testng.TestNG.runSuitesLocally(TestNG.java:1176)
at org.testng.TestNG.runSuites(TestNG.java:1099)
at org.testng.TestNG.run(TestNG.java:1067)
at org.testng.remote.AbstractRemoteTestNG.run(AbstractRemoteTestNG.java:115)
at org.testng.remote.RemoteTestNG.initAndRun(RemoteTestNG.java:251)
at org.testng.remote.RemoteTestNG.main(RemoteTestNG.java:77)
]]>
            </full-stacktrace>
          </exception> <!-- java.lang.AssertionError -->
          <reporter-output>
          </reporter-output>
        </test-method> <!-- loginToSalesForceAppUsingDataProviders -->
        <test-method is-config="true" signature="tearDown()[pri:0, instance:com.tekarck.testCases.TC02_ValidLoginToSalesForce@47faa49c]" started-at="2023-09-05T11:21:41 EDT" name="tearDown" finished-at="2023-09-05T11:21:42 EDT" duration-ms="853" status="PASS">
          <reporter-output>
          </reporter-output>
        </test-method> <!-- tearDown -->
      </class> <!-- com.tekarck.testCases.TC02_ValidLoginToSalesForce -->
    </test> <!-- FIREFOX(failed) -->
  </suite> <!-- Failed suite [crossBrowserTestingSuite] -->
</testng-results>
